Workbook
Name HouseID_List: 'mst_Houses'!$A$2:$A$24
Name BreedID_List: 'mst_Breeds'!$A$2:$A$23
Name FeedID_List: 'mst_FeedTypes'!$A$2:$A$23
Name SupplierID_List: 'mst_Suppliers'!$A$2:$A$24
Name CustomerID_List: 'mst_Customers'!$A$2:$A$23
Name ProductID_List: 'mst_Vaccines_Meds'!$A$2:$A$24
Name UserName_List: 'mst_Users'!$B$2:$B$23
Name FlockID_List: 'reg_Flocks'!$A$2:$A$24
Name List_PaymentMethod: 'mst_Lists'!$A$2:$A$15
Name List_LitterCondition: 'mst_Lists'!$B$2:$B$15
Name List_Ventilation: 'mst_Lists'!$C$2:$C$15
Name List_ExpenseCategory: 'mst_Lists'!$D$2:$D$15
Name List_YesNo: 'mst_Lists'!$E$2:$E$15
Name List_MortalityCause: 'mst_Lists'!$F$2:$F$15
Name List_VaccinationRoute: 'mst_Lists'!$G$2:$G$15
Name EmployeeID_List: 'mst_Employees'!$A$2:$A$24

Sheet Dashboard
A1: FarmNow Limited — Broiler Production Dashboard
A3: ="Live KPI overview across all flocks | Report generated: "&TEXT(TODAY(),"dd mmm yyyy")
A5: Livability % (Active Flocks) | C5: Avg FCR (Active Flocks) | E5: Avg Daily Gain (g/bird) | G5: Mortality % (Active Flocks) | I5: Avg Cost / Bird (ZMW) | K5: Avg Cost / Kg Live Wt (ZMW)
A6: =IFERROR(SUMIFS(calc_KPI_Engine[CurrentBirds],calc_KPI_Engine[Status],"Active")/SUMIFS(calc_KPI_Engine[InitialBirds],calc_KPI_Engine[Status],"Active"),0) | C6: =IFERROR(AVERAGEIFS(calc_KPI_Engine[FCR],calc_KPI_Engine[Status],"Active"),0) | E6: =IFERROR(AVERAGEIFS(calc_KPI_Engine[ADG_g],calc_KPI_Engine[Status],"Active"),0) | G6: =1-IFERROR(SUMIFS(calc_KPI_Engine[CurrentBirds],calc_KPI_Engine[Status],"Active")/SUMIFS(calc_KPI_Engine[InitialBirds],calc_KPI_Engine[Status],"Active"),0) | I6: =IFERROR(AVERAGEIFS(calc_KPI_Engine[CostPerBird_ZMW],calc_KPI_Engine[Status],"Active"),0) | K6: =IFERROR(AVERAGEIFS(calc_KPI_Engine[CostPerKg_ZMW],calc_KPI_Engine[Status],"Active"),0)
A7: ="Target: "&TEXT(INDEX(mst_Settings[Value],MATCH("TargetLivabilityPct",mst_Settings[Parameter],0)),"0.0%") | C7: ="Target: "&TEXT(INDEX(mst_Settings[Value],MATCH("TargetFCR",mst_Settings[Parameter],0)),"0.00") | G7: ="Target: "&TEXT(INDEX(mst_Settings[Value],MATCH("MortalityAlertThresholdPct",mst_Settings[Parameter],0)),"0.00%")
A9: Flock Performance Comparison
A10: Flock | B10: House | C10: Breed | D10: Status | E10: Days On Farm | F10: Livability % | G10: FCR | H10: ADG (g) | I10: Cost/Bird (ZMW) | J10: Cost/Kg (ZMW) | K10: Est. Profit (ZMW)
A11: =calc_KPI_Engine!A2 | B11: =calc_KPI_Engine!B2 | C11: =calc_KPI_Engine!C2 | D11: =calc_KPI_Engine!E2 | E11: =calc_KPI_Engine!F2 | F11: =calc_KPI_Engine!J2 | G11: =calc_KPI_Engine!O2 | H11: =calc_KPI_Engine!P2 | I11: =calc_KPI_Engine!U2 | J11: =calc_KPI_Engine!V2 | K11: =calc_KPI_Engine!W2
A12: =calc_KPI_Engine!A3 | B12: =calc_KPI_Engine!B3 | C12: =calc_KPI_Engine!C3 | D12: =calc_KPI_Engine!E3 | E12: =calc_KPI_Engine!F3 | F12: =calc_KPI_Engine!J3 | G12: =calc_KPI_Engine!O3 | H12: =calc_KPI_Engine!P3 | I12: =calc_KPI_Engine!U3 | J12: =calc_KPI_Engine!V3 | K12: =calc_KPI_Engine!W3
A13: =calc_KPI_Engine!A4 | B13: =calc_KPI_Engine!B4 | C13: =calc_KPI_Engine!C4 | D13: =calc_KPI_Engine!E4 | E13: =calc_KPI_Engine!F4 | F13: =calc_KPI_Engine!J4 | G13: =calc_KPI_Engine!O4 | H13: =calc_KPI_Engine!P4 | I13: =calc_KPI_Engine!U4 | J13: =calc_KPI_Engine!V4 | K13: =calc_KPI_Engine!W4
A14: =calc_KPI_Engine!A5 | B14: =calc_KPI_Engine!B5 | C14: =calc_KPI_Engine!C5 | D14: =calc_KPI_Engine!E5 | E14: =calc_KPI_Engine!F5 | F14: =calc_KPI_Engine!J5 | G14: =calc_KPI_Engine!O5 | H14: =calc_KPI_Engine!P5 | I14: =calc_KPI_Engine!U5 | J14: =calc_KPI_Engine!V5 | K14: =calc_KPI_Engine!W5
A17: Trend & Comparison Charts
A35: Alerts
A36: Flock | B36: Alert
A37: =calc_KPI_Engine!A2 | B37: =IF(calc_KPI_Engine!E2<>"Active","",IF(calc_KPI_Engine!J2<INDEX(mst_Settings[Value],MATCH("TargetLivabilityPct",mst_Settings[Parameter],0)),"Livability below target - investigate mortality",IF(calc_KPI_Engine!O2>INDEX(mst_Settings[Value],MATCH("TargetFCR",mst_Settings[Parameter],0)),"FCR above target - review feed efficiency","Within normal range")))
A38: =calc_KPI_Engine!A3 | B38: =IF(calc_KPI_Engine!E3<>"Active","",IF(calc_KPI_Engine!J3<INDEX(mst_Settings[Value],MATCH("TargetLivabilityPct",mst_Settings[Parameter],0)),"Livability below target - investigate mortality",IF(calc_KPI_Engine!O3>INDEX(mst_Settings[Value],MATCH("TargetFCR",mst_Settings[Parameter],0)),"FCR above target - review feed efficiency","Within normal range")))
A39: =calc_KPI_Engine!A4 | B39: =IF(calc_KPI_Engine!E4<>"Active","",IF(calc_KPI_Engine!J4<INDEX(mst_Settings[Value],MATCH("TargetLivabilityPct",mst_Settings[Parameter],0)),"Livability below target - investigate mortality",IF(calc_KPI_Engine!O4>INDEX(mst_Settings[Value],MATCH("TargetFCR",mst_Settings[Parameter],0)),"FCR above target - review feed efficiency","Within normal range")))
A40: =calc_KPI_Engine!A5 | B40: =IF(calc_KPI_Engine!E5<>"Active","",IF(calc_KPI_Engine!J5<INDEX(mst_Settings[Value],MATCH("TargetLivabilityPct",mst_Settings[Parameter],0)),"Livability below target - investigate mortality",IF(calc_KPI_Engine!O5>INDEX(mst_Settings[Value],MATCH("TargetFCR",mst_Settings[Parameter],0)),"FCR above target - review feed efficiency","Within normal range")))
A42: Inventory & Compliance Alerts
A43: Item | B43: Status
A44: =calc_FeedStockSummary!B2&" feed stock" | B44: =calc_FeedStockSummary!H2&" ("&TEXT(calc_FeedStockSummary!F2,"#,##0")&" kg balance)"
A45: =calc_FeedStockSummary!B3&" feed stock" | B45: =calc_FeedStockSummary!H3&" ("&TEXT(calc_FeedStockSummary!F3,"#,##0")&" kg balance)"
A46: =calc_FeedStockSummary!B4&" feed stock" | B46: =calc_FeedStockSummary!H4&" ("&TEXT(calc_FeedStockSummary!F4,"#,##0")&" kg balance)"
A47: =IF(reg_MedicineStock!A2="","",reg_MedicineStock!E2&" ("&reg_MedicineStock!B2&")") | B47: =IF(reg_MedicineStock!A2="","",reg_MedicineStock!L2)
A48: =IF(reg_MedicineStock!A3="","",reg_MedicineStock!E3&" ("&reg_MedicineStock!B3&")") | B48: =IF(reg_MedicineStock!A3="","",reg_MedicineStock!L3)
A49: =IF(reg_MedicineStock!A4="","",reg_MedicineStock!E4&" ("&reg_MedicineStock!B4&")") | B49: =IF(reg_MedicineStock!A4="","",reg_MedicineStock!L4)
A50: =IF(reg_MedicineStock!A5="","",reg_MedicineStock!E5&" ("&reg_MedicineStock!B5&")") | B50: =IF(reg_MedicineStock!A5="","",reg_MedicineStock!L5)

Sheet Menu_Nav
A1: FarmNow Limited — System Navigation
A4: Go To | B4: Sheet | C4: Description
A5: Dashboard | B5: Dashboard | C5: Live KPI overview, flock comparison, charts and alerts
A6: New Flock Setup | B6: reg_Flocks | C6: Register a new flock/batch (house, breed, placement date)
A7: Daily Mortality Entry | B7: reg_DailyMortality | C7: Log daily bird deaths per flock
A8: Feed Consumption Entry | B8: reg_FeedConsumption | C8: Log daily/weekly feed usage per flock
A9: Weekly Weight Sampling | B9: reg_WeeklyWeights | C9: Log sample bird weights per flock
A10: Vaccination & Health Entry | B10: reg_Vaccination_Health | C10: Log vaccines/medication administered
A11: Sales & Dispatch Entry | B11: reg_Sales_Dispatch | C11: Log bird sales and dispatch to customers
A12: Expense Entry | B12: reg_Expenses | C12: Log farm expenses by category
A13: Environment Readings | B13: reg_EnvironmentReadings | C13: Log house temperature/humidity/ammonia
A14: Flock Performance Report | B14: rpt_FlockPerformance | C14: Printable single-flock performance report
A15: Financial Summary Report | B15: rpt_FinancialSummary | C15: Printable P&L summary across all flocks
... A23: System Settings | B23: mst_Settings | C23: KPI targets and alert thresholds
A25: Note: this Menu_Nav also links directly to every sheet - click a link above to jump straight there.
A26: A VBA-driven entry-form layer (UserForms + macros) ships alongside this workbook - see the README and /VBA_Modules folder.
A27: Additional Registers
A28: Daily Routine Checklist | B28: reg_DailyRoutine | C28: Daily floor-walk: temp/humidity, water, feed, litter, ventilation
A29: Feed Purchases Entry | B29: reg_FeedPurchases | C29: Log feed purchases (supplier, bags, cost, invoice, payment)
A30: Feed Stock Summary | B30: calc_FeedStockSummary | C30: Live balance per feed type with low-stock alert
A31: Medicine Stock Entry | B31: reg_MedicineStock | C31: Log medicine/vaccine receipts, usage, and expiry status
A32: Other Income Entry | B32: reg_OtherIncome | C32: Log non-bird farm income (manure, empty bags, etc.)
A33: Master Data - Employees | B33: mst_Employees | C33: Farm staff directory
A34: Master Data - Dropdown Lists | B34: mst_Lists | C34: Centralised dropdown option lists used across the workbook

Sheet mst_Houses
A1: HouseID | B1: HouseCode | C1: Capacity | D1: LocationZone | E1: Status
A2: 1 | B2: H-01 | C2: 5000 | D2: Zone A | E2: Active
A3: 2 | B3: H-02 | C3: 5000 | D3: Zone A | E3: Active
A4: 3 | B4: H-03 | C4: 4000 | D4: Zone B | E4: Active
A5: 4 | B5: H-04 | C5: 4000 | D5: Zone B | E5: Inactive

Sheet mst_Breeds
A1: BreedID | B1: BreedName | C1: StandardFCR | D1: StandardADG_g
A2: 1 | B2: Ross 308 | C2: 1.65 | D2: 62
A3: 2 | B3: Cobb 500 | C3: 1.68 | D3: 60
A4: 3 | B4: Arbor Acres | C4: 1.7 | D4: 58

Sheet mst_FeedTypes
A1: FeedID | B1: FeedName | C1: Stage | D1: UnitCostPerKg_ZMW | E1: StandardBagWeightKg | F1: MinStockKg
A2: 1 | B2: Starter Mash | C2: Starter | D2: 12.5 | E2: 50 | F2: 300
A3: 2 | B3: Grower Mash | C3: Grower | D3: 11.8 | E3: 50 | F3: 400
A4: 3 | B4: Finisher Mash | C4: Finisher | D4: 11.2 | E4: 50 | F4: 400

Sheet mst_Suppliers
A1: SupplierID | B1: SupplierName | C1: Contact | D1: Email | E1: Category | F1: LeadTimeDays
A2: 1 | B2: Zamchick Hatchery | C2: +260-97-111-2222 | D2: sales@zamchick.example | E2: Day-Old Chicks | F2: 2
A3: 2 | B3: National Milling Co | C3: +260-96-333-4444 | D3: orders@natmill.example | E3: Feed | F3: 1
A4: 3 | B4: AgroVet Supplies Ltd | C4: +260-95-555-6666 | D4: info@agrovet.example | E4: Veterinary | F4: 3
A5: 4 | B5: Lusaka Wood Shavings Ltd | C5: +260-97-888-1111 | D5: sales@lusakawood.example | E5: Bedding/Litter | F5: 2

Sheet mst_Customers
A1: CustomerID | B1: CustomerName | C1: Contact | D1: Address | E1: PriceTier | F1: PaymentTerms
A2: 1 | B2: Shoprite Lusaka | C2: +260-21-123-4567 | D2: Cairo Road, Lusaka | E2: Wholesale | F2: 30 Days Credit
A3: 2 | B3: Melissa Poultry Traders | C3: +260-97-777-8888 | D3: Kabwata, Lusaka | E3: Retail | F3: Cash on Delivery
A4: 3 | B4: City Market Vendors Assoc | C4: +260-96-222-3333 | D4: City Market, Lusaka | E4: Bulk | F4: Cash on Delivery

Sheet mst_Vaccines_Meds
A1: ProductID | B1: ProductName | C1: Type | D1: DosageUnit | E1: WithdrawalDays
A2: 1 | B2: Newcastle Disease Vaccine (Lasota) | C2: Vaccine | D2: ml/bird | E2: 0
A3: 2 | B3: Gumboro Vaccine (IBD) | C3: Vaccine | D3: ml/bird | E3: 0
A4: 3 | B4: Amoxicillin Oral Solution | C4: Antibiotic | D4: ml/L water | E4: 7
A5: 4 | B5: Multivitamin Booster | C5: Supplement | D5: ml/L water | E5: 0

Sheet mst_Users
A1: UserID | B1: UserName | C1: Role
A2: 1 | B2: A. Mwansa | C2: Admin
A3: 2 | B3: B. Tembo | C3: Supervisor
A4: 3 | B4: C. Banda | C4: Entry Clerk

Sheet mst_Settings
A1: Parameter | B1: Value
A2: CompanyName | B2: FarmNow Limited
A3: Location | B3: Lusaka, Zambia
A4: Phone | B4: +260 000 000000
A5: Email | B5: info@farmnow.example
A6: CurrencySymbol | B6: K
A7: ReportCurrency | B7: ZMW
A8: TargetFCR | B8: 1.7
A9: TargetLivabilityPct | B9: 0.95
A10: MortalityAlertThresholdPct | B10: 0.02
A11: MedicineExpiryWarningDays | B11: 30
A12: CurrentFlockCounter | B12: 4

Sheet mst_Lists
A1: PaymentMethod | B1: LitterCondition | C1: Ventilation | D1: ExpenseCategory | E1: YesNo | F1: MortalityCause | G1: VaccinationRoute
A2: Cash | B2: Dry | C2: Good | D2: Day-Old Chicks | E2: Yes | F2: Normal Culling | G2: Eye Drop
A3: Mobile Money | B3: Damp | C3: Fair | D3: Bedding/Litter | E3: No | F3: Heat Stress | G3: Drinking Water
A4: Bank Transfer | B4: Wet | C4: Poor | D4: Utilities | F4: Disease | G4: Injection
A5: Cheque | B5: Needs Changing | D5: Labour | F5: Predator | G5: Spray
A6: Credit | D6: Transport | F6: Cold Stress
D7: Veterinary | F7: Other
D8: Heater/Fuel
D9: Miscellaneous

Sheet reg_Flocks
A1: FlockID | B1: HouseID | C1: BreedID | D1: PlacedDate | E1: InitialBirdCount | F1: SupplierID | G1: ExpectedDispatchDate | H1: Status
A2: FLK-001 | B2: 1 | C2: 1 | D2: 46162 | E2: 5000 | F2: 1 | G2: 46204 | H2: Closed
A3: FLK-002 | B3: 2 | C3: 2 | D3: 46198 | E3: 5000 | F3: 1 | G3: 46240 | H3: Active
A4: FLK-003 | B4: 3 | C4: 1 | D4: 46218 | E4: 4000 | F4: 1 | G4: 46260 | H4: Active
A5: FLK-004 | B5: 1 | C5: 3 | D5: 46235 | E5: 5000 | F5: 1 | G5: 46277 | H5: Active

Sheet reg_DailyMortality
A1: EntryID | B1: FlockID | C1: Date | D1: MortalityCount | E1: Cause | F1: CumulativeMortality | G1: EnteredBy | H1: IsActive
A2: MORT-0001 | B2: FLK-001 | C2: 46162 | D2: 8 | E2: Normal Culling | F2: =SUMIFS(reg_DailyMortality[MortalityCount],reg_DailyMortality[FlockID],$B2,reg_DailyMortality[Date],"<="&$C2) | G2: C. Banda | H2: Yes
A3: MORT-0002 | B3: FLK-001 | C3: 46166 | D3: 7 | E3: Heat Stress | F3: =SUMIFS(reg_DailyMortality[MortalityCount],reg_DailyMortality[FlockID],$B3,reg_DailyMortality[Date],"<="&$C3) | G3: B. Tembo | H3: Yes
A4: MORT-0003 | B4: FLK-001 | C4: 46170 | D4: 1 | E4: Disease | F4: =SUMIFS(reg_DailyMortality[MortalityCount],reg_DailyMortality[FlockID],$B4,reg_DailyMortality[Date],"<="&$C4) | G4: C. Banda | H4: Yes
A5: MORT-0004 | B5: FLK-001 | C5: 46174 | D5: 3 | E5: Normal Culling | F5: =SUMIFS(reg_DailyMortality[MortalityCount],reg_DailyMortality[FlockID],$B5,reg_DailyMortality[Date],"<="&$C5) | G5: C. Banda | H5: Yes
A6: MORT-0005 | B6: FLK-001 | C6: 46178 | D6: 2 | E6: Normal Culling | F6: =SUMIFS(reg_DailyMortality[MortalityCount],reg_DailyMortality[FlockID],$B6,reg_DailyMortality[Date],"<="&$C6) | G6: B. Tembo | H6: Yes
A7: MORT-0006 | B7: FLK-001 | C7: 46182 | D7: 1 | E7: Heat Stress | F7: =SUMIFS(reg_DailyMortality[MortalityCount],reg_DailyMortality[FlockID],$B7,reg_DailyMortality[Date],"<="&$C7) | G7: C. Banda | H7: Yes
A8: MORT-0007 | B8: FLK-001 | C8: 46186 | D8: 2 | E8: Disease | F8: =SUMIFS(reg_DailyMortality[MortalityCount],reg_DailyMortality[FlockID],$B8,reg_DailyMortality[Date],"<="&$C8) | G8: C. Banda | H8: Yes
A9: MORT-0008 | B9: FLK-001 | C9: 46190 | D9: 1 | E9: Normal Culling | F9: =SUMIFS(reg_DailyMortality[MortalityCount],reg_DailyMortality[FlockID],$B9,reg_DailyMortality[Date],"<="&$C9) | G9: B. Tembo | H9: Yes
A10: MORT-0009 | B10: FLK-001 | C10: 46194 | D10: 1 | E10: Normal Culling | F10: =SUMIFS(reg_DailyMortality[MortalityCount],reg_DailyMortality[FlockID],$B10,reg_DailyMortality[Date],"<="&$C10) | G10: C. Banda | H10: Yes
A11: MORT-0010 | B11: FLK-001 | C11: 46198 | D11: 2 | E11: Heat Stress | F11: =SUMIFS(reg_DailyMortality[MortalityCount],reg_DailyMortality[FlockID],$B11,reg_DailyMortality[Date],"<="&$C11) | G11: C. Banda | H11: Yes
A12: MORT-0011 | B12: FLK-001 | C12: 46202 | D12: 1 | E12: Disease | F12: =SUMIFS(reg_DailyMortality[MortalityCount],reg_DailyMortality[FlockID],$B12,reg_DailyMortality[Date],"<="&$C12) | G12: B. Tembo | H12: Yes
A13: MORT-0012 | B13: FLK-002 | C13: 46198 | D13: 10 | E13: Normal Culling | F13: =SUMIFS(reg_DailyMortality[MortalityCount],reg_DailyMortality[FlockID],$B13,reg_DailyMortality[Date],"<="&$C13) | G13: C. Banda | H13: Yes
... A32: MORT-0031 | B32: FLK-004 | C32: 46239 | D32: 7 | E32: Heat Stress | F32: =SUMIFS(reg_DailyMortality[MortalityCount],reg_DailyMortality[FlockID],$B32,reg_DailyMortality[Date],"<="&$C32) | G32: B. Tembo | H32: Yes

Sheet reg_FeedConsumption
A1: EntryID | B1: FlockID | C1: Date | D1: FeedID | E1: KgUsed | F1: CostZMW | G1: RunningTotalKg | H1: EnteredBy | I1: IsActive
A2: FEED-0001 | B2: FLK-001 | C2: 46166 | D2: 1 | E2: 600 | F2: =ROUND($E2*INDEX(mst_FeedTypes[UnitCostPerKg_ZMW],MATCH($D2,mst_FeedTypes[FeedID],0)),2) | G2: =SUMIFS(reg_FeedConsumption[KgUsed],reg_FeedConsumption[FlockID],$B2,reg_FeedConsumption[Date],"<="&$C2) | H2: B. Tembo | I2: Yes
A3: FEED-0002 | B3: FLK-001 | C3: 46170 | D3: 1 | E3: 800 | F3: =ROUND($E3*INDEX(mst_FeedTypes[UnitCostPerKg_ZMW],MATCH($D3,mst_FeedTypes[FeedID],0)),2) | G3: =SUMIFS(reg_FeedConsumption[KgUsed],reg_FeedConsumption[FlockID],$B3,reg_FeedConsumption[Date],"<="&$C3) | H3: C. Banda | I3: Yes
A4: FEED-0003 | B4: FLK-001 | C4: 46174 | D4: 2 | E4: 1000 | F4: =ROUND($E4*INDEX(mst_FeedTypes[UnitCostPerKg_ZMW],MATCH($D4,mst_FeedTypes[FeedID],0)),2) | G4: =SUMIFS(reg_FeedConsumption[KgUsed],reg_FeedConsumption[FlockID],$B4,reg_FeedConsumption[Date],"<="&$C4) | H4: C. Banda | I4: Yes
A5: FEED-0004 | B5: FLK-001 | C5: 46178 | D5: 2 | E5: 1200 | F5: =ROUND($E5*INDEX(mst_FeedTypes[UnitCostPerKg_ZMW],MATCH($D5,mst_FeedTypes[FeedID],0)),2) | G5: =SUMIFS(reg_FeedConsumption[KgUsed],reg_FeedConsumption[FlockID],$B5,reg_FeedConsumption[Date],"<="&$C5) | H5: B. Tembo | I5: Yes
A6: FEED-0005 | B6: FLK-001 | C6: 46182 | D6: 2 | E6: 1400 | F6: =ROUND($E6*INDEX(mst_FeedTypes[UnitCostPerKg_ZMW],MATCH($D6,mst_FeedTypes[FeedID],0)),2) | G6: =SUMIFS(reg_FeedConsumption[KgUsed],reg_FeedConsumption[FlockID],$B6,reg_FeedConsumption[Date],"<="&$C6) | H6: C. Banda | I6: Yes
A7: FEED-0006 | B7: FLK-001 | C7: 46186 | D7: 2 | E7: 1600 | F7: =ROUND($E7*INDEX(mst_FeedTypes[UnitCostPerKg_ZMW],MATCH($D7,mst_FeedTypes[FeedID],0)),2) | G7: =SUMIFS(reg_FeedConsumption[KgUsed],reg_FeedConsumption[FlockID],$B7,reg_FeedConsumption[Date],"<="&$C7) | H7: C. Banda | I7: Yes
A8: FEED-0007 | B8: FLK-001 | C8: 46190 | D8: 3 | E8: 1800 | F8: =ROUND($E8*INDEX(mst_FeedTypes[UnitCostPerKg_ZMW],MATCH($D8,mst_FeedTypes[FeedID],0)),2) | G8: =SUMIFS(reg_FeedConsumption[KgUsed],reg_FeedConsumption[FlockID],$B8,reg_FeedConsumption[Date],"<="&$C8) | H8: B. Tembo | I8: Yes
A9: FEED-0008 | B9: FLK-001 | C9: 46194 | D9: 3 | E9: 2000 | F9: =ROUND($E9*INDEX(mst_FeedTypes[UnitCostPerKg_ZMW],MATCH($D9,mst_FeedTypes[FeedID],0)),2) | G9: =SUMIFS(reg_FeedConsumption[KgUsed],reg_FeedConsumption[FlockID],$B9,reg_FeedConsumption[Date],"<="&$C9) | H9: C. Banda | I9: Yes
A10: FEED-0009 | B10: FLK-001 | C10: 46198 | D10: 3 | E10: 2200 | F10: =ROUND($E10*INDEX(mst_FeedTypes[UnitCostPerKg_ZMW],MATCH($D10,mst_FeedTypes[FeedID],0)),2) | G10: =SUMIFS(reg_FeedConsumption[KgUsed],reg_FeedConsumption[FlockID],$B10,reg_FeedConsumption[Date],"<="&$C10) | H10: C. Banda | I10: Yes
A11: FEED-0010 | B11: FLK-001 | C11: 46202 | D11: 3 | E11: 2400 | F11: =ROUND($E11*INDEX(mst_FeedTypes[UnitCostPerKg_ZMW],MATCH($D11,mst_FeedTypes[FeedID],0)),2) | G11: =SUMIFS(reg_FeedConsumption[KgUsed],reg_FeedConsumption[FlockID],$B11,reg_FeedConsumption[Date],"<="&$C11) | H11: B. Tembo | I11: Yes
A12: FEED-0011 | B12: FLK-002 | C12: 46202 | D12: 1 | E12: 720 | F12: =ROUND($E12*INDEX(mst_FeedTypes[UnitCostPerKg_ZMW],MATCH($D12,mst_FeedTypes[FeedID],0)),2) | G12: =SUMIFS(reg_FeedConsumption[KgUsed],reg_FeedConsumption[FlockID],$B12,reg_FeedConsumption[Date],"<="&$C12) | H12: B. Tembo | I12: Yes
A13: FEED-0012 | B13: FLK-002 | C13: 46206 | D13: 1 | E13: 960 | F13: =ROUND($E13*INDEX(mst_FeedTypes[UnitCostPerKg_ZMW],MATCH($D13,mst_FeedTypes[FeedID],0)),2) | G13: =SUMIFS(reg_FeedConsumption[KgUsed],reg_FeedConsumption[FlockID],$B13,reg_FeedConsumption[Date],"<="&$C13) | H13: C. Banda | I13: Yes
... A28: FEED-0027 | B28: FLK-004 | C28: 46239 | D28: 1 | E28: 630 | F28: =ROUND($E28*INDEX(mst_FeedTypes[UnitCostPerKg_ZMW],MATCH($D28,mst_FeedTypes[FeedID],0)),2) | G28: =SUMIFS(reg_FeedConsumption[KgUsed],reg_FeedConsumption[FlockID],$B28,reg_FeedConsumption[Date],"<="&$C28) | H28: B. Tembo | I28: Yes

Sheet reg_WeeklyWeights
A1: EntryID | B1: FlockID | C1: Date | D1: WeekNo | E1: SampleSize | F1: AvgBodyWeightG | G1: AgeDays | H1: ADG_g | I1: EnteredBy | J1: IsActive
A2: WGT-0001 | B2: FLK-001 | C2: 46169 | D2: 1 | E2: 50 | F2: 180 | G2: =$C2-INDEX(reg_Flocks[PlacedDate],MATCH($B2,reg_Flocks[FlockID],0)) | H2: =IFERROR($F2/$G2,0) | I2: B. Tembo | J2: Yes
A3: WGT-0002 | B3: FLK-001 | C3: 46176 | D3: 2 | E3: 50 | F3: 430 | G3: =$C3-INDEX(reg_Flocks[PlacedDate],MATCH($B3,reg_Flocks[FlockID],0)) | H3: =IFERROR($F3/$G3,0) | I3: C. Banda | J3: Yes
A4: WGT-0003 | B4: FLK-001 | C4: 46183 | D4: 3 | E4: 50 | F4: 800 | G4: =$C4-INDEX(reg_Flocks[PlacedDate],MATCH($B4,reg_Flocks[FlockID],0)) | H4: =IFERROR($F4/$G4,0) | I4: C. Banda | J4: Yes
A5: WGT-0004 | B5: FLK-001 | C5: 46190 | D5: 4 | E5: 50 | F5: 1300 | G5: =$C5-INDEX(reg_Flocks[PlacedDate],MATCH($B5,reg_Flocks[FlockID],0)) | H5: =IFERROR($F5/$G5,0) | I5: B. Tembo | J5: Yes
A6: WGT-0005 | B6: FLK-001 | C6: 46197 | D6: 5 | E6: 50 | F6: 1850 | G6: =$C6-INDEX(reg_Flocks[PlacedDate],MATCH($B6,reg_Flocks[FlockID],0)) | H6: =IFERROR($F6/$G6,0) | I6: C. Banda | J6: Yes
A7: WGT-0006 | B7: FLK-001 | C7: 46204 | D7: 6 | E7: 50 | F7: 2400 | G7: =$C7-INDEX(reg_Flocks[PlacedDate],MATCH($B7,reg_Flocks[FlockID],0)) | H7: =IFERROR($F7/$G7,0) | I7: C. Banda | J7: Yes
A8: WGT-0007 | B8: FLK-002 | C8: 46205 | D8: 1 | E8: 50 | F8: 180 | G8: =$C8-INDEX(reg_Flocks[PlacedDate],MATCH($B8,reg_Flocks[FlockID],0)) | H8: =IFERROR($F8/$G8,0) | I8: B. Tembo | J8: Yes
A9: WGT-0008 | B9: FLK-002 | C9: 46212 | D9: 2 | E9: 50 | F9: 430 | G9: =$C9-INDEX(reg_Flocks[PlacedDate],MATCH($B9,reg_Flocks[FlockID],0)) | H9: =IFERROR($F9/$G9,0) | I9: C. Banda | J9: Yes
A10: WGT-0009 | B10: FLK-002 | C10: 46219 | D10: 3 | E10: 50 | F10: 800 | G10: =$C10-INDEX(reg_Flocks[PlacedDate],MATCH($B10,reg_Flocks[FlockID],0)) | H10: =IFERROR($F10/$G10,0) | I10: C. Banda | J10: Yes
A11: WGT-0010 | B11: FLK-002 | C11: 46226 | D11: 4 | E11: 50 | F11: 1300 | G11: =$C11-INDEX(reg_Flocks[PlacedDate],MATCH($B11,reg_Flocks[FlockID],0)) | H11: =IFERROR($F11/$G11,0) | I11: B. Tembo | J11: Yes
A12: WGT-0011 | B12: FLK-002 | C12: 46233 | D12: 5 | E12: 50 | F12: 1850 | G12: =$C12-INDEX(reg_Flocks[PlacedDate],MATCH($B12,reg_Flocks[FlockID],0)) | H12: =IFERROR($F12/$G12,0) | I12: C. Banda | J12: Yes
A13: WGT-0012 | B13: FLK-002 | C13: 46240 | D13: 6 | E13: 50 | F13: 2400 | G13: =$C13-INDEX(reg_Flocks[PlacedDate],MATCH($B13,reg_Flocks[FlockID],0)) | H13: =IFERROR($F13/$G13,0) | I13: C. Banda | J13: Yes
... A17: WGT-0016 | B17: FLK-004 | C17: 46242 | D17: 1 | E17: 50 | F17: 180 | G17: =$C17-INDEX(reg_Flocks[PlacedDate],MATCH($B17,reg_Flocks[FlockID],0)) | H17: =IFERROR($F17/$G17,0) | I17: B. Tembo | J17: Yes

Sheet reg_Vaccination_Health
A1: EntryID | B1: FlockID | C1: Date | D1: ProductID | E1: DosageGiven | F1: Route | G1: AdministeredBy | H1: IsActive | I1: RankInFlock | J1: CompositeKey
A2: HLTH-0001 | B2: FLK-001 | C2: 46163 | D2: 1 | E2: 1 drop/bird | F2: Eye Drop | G2: B. Tembo | H2: Yes | I2: =COUNTIFS(reg_Vaccination_Health[FlockID],$B2,reg_Vaccination_Health[EntryID],"<="&$A2) | J2: =$B2&"-"&$I2
A3: HLTH-0002 | B3: FLK-001 | C3: 46176 | D3: 2 | E3: Per label / 1000 birds | F3: Drinking Water | G3: B. Tembo | H3: Yes | I3: =COUNTIFS(reg_Vaccination_Health[FlockID],$B3,reg_Vaccination_Health[EntryID],"<="&$A3) | J3: =$B3&"-"&$I3
A4: HLTH-0003 | B4: FLK-001 | C4: 46164 | D4: 4 | E4: 1 ml/L water | F4: Drinking Water | G4: B. Tembo | H4: Yes | I4: =COUNTIFS(reg_Vaccination_Health[FlockID],$B4,reg_Vaccination_Health[EntryID],"<="&$A4) | J4: =$B4&"-"&$I4
A5: HLTH-0004 | B5: FLK-002 | C5: 46199 | D5: 1 | E5: 1 drop/bird | F5: Eye Drop | G5: B. Tembo | H5: Yes | I5: =COUNTIFS(reg_Vaccination_Health[FlockID],$B5,reg_Vaccination_Health[EntryID],"<="&$A5) | J5: =$B5&"-"&$I5
A6: HLTH-0005 | B6: FLK-002 | C6: 46212 | D6: 2 | E6: Per label / 1000 birds | F6: Drinking Water | G6: B. Tembo | H6: Yes | I6: =COUNTIFS(reg_Vaccination_Health[FlockID],$B6,reg_Vaccination_Health[EntryID],"<="&$A6) | J6: =$B6&"-"&$I6
A7: HLTH-0006 | B7: FLK-002 | C7: 46218 | D7: 3 | E7: 2 ml/L water x 5 days | F7: Drinking Water | G7: B. Tembo | H7: Yes | I7: =COUNTIFS(reg_Vaccination_Health[FlockID],$B7,reg_Vaccination_Health[EntryID],"<="&$A7) | J7: =$B7&"-"&$I7
A8: HLTH-0007 | B8: FLK-002 | C8: 46200 | D8: 4 | E8: 1 ml/L water | F8: Drinking Water | G8: B. Tembo | H8: Yes | I8: =COUNTIFS(reg_Vaccination_Health[FlockID],$B8,reg_Vaccination_Health[EntryID],"<="&$A8) | J8: =$B8&"-"&$I8
A9: HLTH-0008 | B9: FLK-003 | C9: 46219 | D9: 1 | E9: 1 drop/bird | F9: Eye Drop | G9: B. Tembo | H9: Yes | I9: =COUNTIFS(reg_Vaccination_Health[FlockID],$B9,reg_Vaccination_Health[EntryID],"<="&$A9) | J9: =$B9&"-"&$I9
A10: HLTH-0009 | B10: FLK-003 | C10: 46232 | D10: 2 | E10: Per label / 1000 birds | F10: Drinking Water | G10: B. Tembo | H10: Yes | I10: =COUNTIFS(reg_Vaccination_Health[FlockID],$B10,reg_Vaccination_Health[EntryID],"<="&$A10) | J10: =$B10&"-"&$I10
A11: HLTH-0010 | B11: FLK-003 | C11: 46220 | D11: 4 | E11: 1 ml/L water | F11: Drinking Water | G11: B. Tembo | H11: Yes | I11: =COUNTIFS(reg_Vaccination_Health[FlockID],$B11,reg_Vaccination_Health[EntryID],"<="&$A11) | J11: =$B11&"-"&$I11
A12: HLTH-0011 | B12: FLK-004 | C12: 46236 | D12: 1 | E12: 1 drop/bird | F12: Eye Drop | G12: B. Tembo | H12: Yes | I12: =COUNTIFS(reg_Vaccination_Health[FlockID],$B12,reg_Vaccination_Health[EntryID],"<="&$A12) | J12: =$B12&"-"&$I12
A13: HLTH-0012 | B13: FLK-004 | C13: 46237 | D13: 4 | E13: 1 ml/L water | F13: Drinking Water | G13: B. Tembo | H13: Yes | I13: =COUNTIFS(reg_Vaccination_Health[FlockID],$B13,reg_Vaccination_Health[EntryID],"<="&$A13) | J13: =$B13&"-"&$I13

Sheet reg_Sales_Dispatch
A1: EntryID | B1: FlockID | C1: Date | D1: CustomerID | E1: BirdsDispatched | F1: TotalLiveWeightKg | G1: PricePerKg_ZMW | H1: PricePerBird_ZMW | I1: TransportCost_ZMW | J1: TotalValue_ZMW | K1: AmountPaid_ZMW | L1: OutstandingBalance_ZMW | M1: InvoiceNo | N1: EnteredBy | O1: IsActive
A2: SALE-0001 | B2: FLK-001 | C2: 46204 | D2: 1 | E2: 3000 | F2: 6750 | G2: 42.5 | H2: 0 | I2: 350 | J2: =ROUND(IF($H2>0,$E2*$H2,$F2*$G2)+$I2,2) | K2: 287225 | L2: =$J2-$K2 | M2: INV-2026-0142 | N2: A. Mwansa | O2: Yes
A3: SALE-0002 | B3: FLK-001 | C3: 46204 | D3: 3 | E3: 1950 | F3: 4387.5 | G3: 41 | H3: 0 | I3: 300 | J3: =ROUND(IF($H3>0,$E3*$H3,$F3*$G3)+$I3,2) | K3: 150000 | L3: =$J3-$K3 | M3: INV-2026-0143 | N3: A. Mwansa | O3: Yes

Sheet reg_Expenses
A1: EntryID | B1: FlockID | C1: Date | D1: ExpenseCategory | E1: SupplierID | F1: Quantity | G1: UnitCost_ZMW | H1: Amount_ZMW | I1: PaymentMethod | J1: PaymentRef | K1: ApprovedBy | L1: EnteredBy | M1: IsActive
A2: EXP-0001 | B2: FLK-001 | C2: 46161 | D2: Bedding/Litter | E2: 4 | F2: 1 | G2: 1800 | H2: =ROUND($F2*$G2,2) | I2: Mobile Money | J2: PMT-1001 | K2: A. Mwansa | L2: A. Mwansa | M2: Yes
A3: EXP-0002 | B3: FLK-001 | C3: 46162 | D3: Day-Old Chicks | E3: 1 | F3: 5000 | G3: 4.5 | H3: =ROUND($F3*$G3,2) | I3: Bank Transfer | J3: PMT-1002 | K3: A. Mwansa | L3: A. Mwansa | M3: Yes
A4: EXP-0003 | B4: FLK-001 | C4: 46183 | D4: Veterinary | E4: 3 | F4: 1 | G4: 950 | H4: =ROUND($F4*$G4,2) | I4: Cash | J4: PMT-1005 | K4: B. Tembo | L4: B. Tembo | M4: Yes
A5: EXP-0004 | B5: FLK-001 | C5: 46201 | D5: Transport | F5: 1 | G5: 1200 | H5: =ROUND($F5*$G5,2) | I5: Cash | J5: PMT-1009 | K5: A. Mwansa | L5: A. Mwansa | M5: Yes
A6: EXP-0005 | B6: FLK-001 | C6: 46203 | D6: Labour | F6: 1 | G6: 2400 | H6: =ROUND($F6*$G6,2) | I6: Mobile Money | J6: PMT-1010 | K6: A. Mwansa | L6: A. Mwansa | M6: Yes
A7: EXP-0006 | B7: FLK-002 | C7: 46197 | D7: Bedding/Litter | E7: 4 | F7: 1 | G7: 1800 | H7: =ROUND($F7*$G7,2) | I7: Mobile Money | J7: PMT-1011 | K7: A. Mwansa | L7: A. Mwansa | M7: Yes
A8: EXP-0007 | B8: FLK-002 | C8: 46198 | D8: Day-Old Chicks | E8: 1 | F8: 5000 | G8: 4.6 | H8: =ROUND($F8*$G8,2) | I8: Bank Transfer | J8: PMT-1012 | K8: A. Mwansa | L8: A. Mwansa | M8: Yes
A9: EXP-0008 | B9: FLK-002 | C9: 46218 | D9: Veterinary | E9: 3 | F9: 1 | G9: 1100 | H9: =ROUND($F9*$G9,2) | I9: Cash | J9: PMT-1018 | K9: B. Tembo | L9: B. Tembo | M9: Yes
A10: EXP-0009 | B10: FLK-002 | C10: 46231 | D10: Labour | F10: 1 | G10: 2400 | H10: =ROUND($F10*$G10,2) | I10: Mobile Money | J10: PMT-1024 | K10: A. Mwansa | L10: A. Mwansa | M10: Yes
A11: EXP-0010 | B11: FLK-003 | C11: 46217 | D11: Bedding/Litter | E11: 4 | F11: 1 | G11: 1450 | H11: =ROUND($F11*$G11,2) | I11: Cash | J11: PMT-1026 | K11: A. Mwansa | L11: A. Mwansa | M11: Yes
A12: EXP-0011 | B12: FLK-003 | C12: 46218 | D12: Day-Old Chicks | E12: 1 | F12: 4000 | G12: 4.5 | H12: =ROUND($F12*$G12,2) | I12: Bank Transfer | J12: PMT-1027 | K12: A. Mwansa | L12: A. Mwansa | M12: Yes
A13: EXP-0012 | B13: FLK-003 | C13: 46235 | D13: Labour | F13: 1 | G13: 2000 | H13: =ROUND($F13*$G13,2) | I13: Mobile Money | J13: PMT-1032 | K13: B. Tembo | L13: B. Tembo | M13: Yes
A14: EXP-0013 | B14: FLK-004 | C14: 46234 | D14: Bedding/Litter | E14: 4 | F14: 1 | G14: 1800 | H14: =ROUND($F14*$G14,2) | I14: Cash | J14: PMT-1035 | K14: A. Mwansa | L14: A. Mwansa | M14: Yes
A15: EXP-0014 | B15: FLK-004 | C15: 46235 | D15: Day-Old Chicks | E15: 1 | F15: 5000 | G15: 4.5 | H15: =ROUND($F15*$G15,2) | I15: Bank Transfer | J15: PMT-1036 | K15: A. Mwansa | L15: A. Mwansa | M15: Yes
A16: EXP-0015 | B16: Overhead | C16: 46235 | D16: Utilities | F16: 1 | G16: 3200 | H16: =ROUND($F16*$G16,2) | I16: Bank Transfer | J16: PMT-1037 | K16: A. Mwansa | L16: A. Mwansa | M16: Yes

Sheet reg_EnvironmentReadings
A1: EntryID | B1: HouseID | C1: Date | D1: Time | E1: TemperatureC | F1: HumidityPct | G1: AmmoniaPPM | H1: EnteredBy | I1: IsActive
A2: ENV-0001 | B2: 1 | C2: 46162 | D2: 07:00 | E2: 32 | F2: 62 | G2: 8 | H2: C. Banda | I2: Yes
A3: ENV-0002 | B3: 1 | C3: 46167 | D3: 07:00 | E3: 31.2 | F3: 62 | G3: 8 | H3: C. Banda | I3: Yes
A4: ENV-0003 | B4: 1 | C4: 46172 | D4: 07:00 | E4: 30.5 | F4: 62 | G4: 8 | H4: C. Banda | I4: Yes
A5: ENV-0004 | B5: 1 | C5: 46177 | D5: 07:00 | E5: 29.8 | F5: 62 | G5: 8 | H5: C. Banda | I5: Yes
A6: ENV-0005 | B6: 1 | C6: 46182 | D6: 07:00 | E6: 29 | F6: 62 | G6: 8 | H6: C. Banda | I6: Yes
A7: ENV-0006 | B7: 1 | C7: 46187 | D7: 07:00 | E7: 28.2 | F7: 62 | G7: 8 | H7: C. Banda | I7: Yes
A8: ENV-0007 | B8: 1 | C8: 46192 | D8: 07:00 | E8: 27.5 | F8: 62 | G8: 8 | H8: C. Banda | I8: Yes
A9: ENV-0008 | B9: 1 | C9: 46197 | D9: 07:00 | E9: 26.8 | F9: 62 | G9: 8 | H9: C. Banda | I9: Yes
A10: ENV-0009 | B10: 1 | C10: 46202 | D10: 07:00 | E10: 26 | F10: 62 | G10: 8 | H10: C. Banda | I10: Yes
A11: ENV-0010 | B11: 2 | C11: 46198 | D11: 07:00 | E11: 32 | F11: 62 | G11: 8 | H11: C. Banda | I11: Yes
A12: ENV-0011 | B12: 2 | C12: 46203 | D12: 07:00 | E12: 31.2 | F12: 62 | G12: 8 | H12: C. Banda | I12: Yes
A13: ENV-0012 | B13: 2 | C13: 46208 | D13: 07:00 | E13: 30.5 | F13: 62 | G13: 8 | H13: C. Banda | I13: Yes
... A26: ENV-0025 | B26: 1 | C26: 46240 | D26: 07:00 | E26: 31.2 | F26: 62 | G26: 8 | H26: C. Banda | I26: Yes

Sheet reg_OtherIncome
A1: EntryID | B1: Date | C1: Source | D1: Description | E1: Amount_ZMW | F1: PaymentMethod | G1: ReceivedBy | H1: IsActive
A2: INC-0001 | B2: 46225 | C2: Manure Sales | D2: Sold manure from House 1 | E2: 450 | F2: Cash | G2: G. Tembo | H2: Yes
A3: INC-0002 | B3: 46235 | C3: Empty Bag Sales | D3: Sold used feed bags | E3: 120 | F3: Cash | G3: G. Tembo | H3: Yes
A4: INC-0003 | B4: 46239 | C4: Manure Sales | D4: Sold manure from House 2 | E4: 380 | F4: Mobile Money | G4: G. Tembo | H4: Yes

Sheet calc_KPI_Engine
A1: FlockID | B1: HouseCode | C1: BreedName | D1: PlacedDate | E1: Status | F1: DaysOnFarm | G1: InitialBirds | H1: TotalMortality | I1: CurrentBirds | J1: LivabilityPct | K1: TotalFeedKg | L1: TotalFeedCost_ZMW | M1: LatestWeightDate | N1: LatestAvgWeightG | O1: FCR | P1: ADG_g | Q1: TotalExpenses_ZMW | R1: MedicineCost_ZMW | S1: TotalSalesValue_ZMW | T1: BirdsSold | U1: CostPerBird_ZMW | V1: CostPerKg_ZMW | W1: EstimatedProfit_ZMW | X1: BreakEvenPricePerBird_ZMW
A2: =IFERROR(INDEX(reg_Flocks[FlockID],ROW()-1),"") | B2: =IF($A2="","",IFERROR(INDEX(mst_Houses[HouseCode],MATCH(INDEX(reg_Flocks[HouseID],MATCH($A2,reg_Flocks[FlockID],0)),mst_Houses[HouseID],0)),"")) | C2: =IF($A2="","",IFERROR(INDEX(mst_Breeds[BreedName],MATCH(INDEX(reg_Flocks[BreedID],MATCH($A2,reg_Flocks[FlockID],0)),mst_Breeds[BreedID],0)),"")) | D2: =IF($A2="","",INDEX(reg_Flocks[PlacedDate],MATCH($A2,reg_Flocks[FlockID],0))) | E2: =IF($A2="","",INDEX(reg_Flocks[Status],MATCH($A2,reg_Flocks[FlockID],0))) | F2: =IF($A2="","",TODAY()-$D2) | G2: =IF($A2="","",INDEX(reg_Flocks[InitialBirdCount],MATCH($A2,reg_Flocks[FlockID],0))) | H2: =IF($A2="","",SUMIFS(reg_DailyMortality[MortalityCount],reg_DailyMortality[FlockID],$A2)) | I2: =IF($A2="","",$G2-$H2) | J2: =IF($A2="","",IFERROR($I2/$G2,0)) | K2: =IF($A2="","",SUMIFS(reg_FeedConsumption[KgUsed],reg_FeedConsumption[FlockID],$A2)) | L2: =IF($A2="","",SUMIFS(reg_FeedConsumption[CostZMW],reg_FeedConsumption[FlockID],$A2)) | M2: =IF($A2="","",IFERROR(_xlfn.MAXIFS(reg_WeeklyWeights[Date],reg_WeeklyWeights[FlockID],$A2),"")) | N2: =IF($A2="","",IFERROR(SUMIFS(reg_WeeklyWeights[AvgBodyWeightG],reg_WeeklyWeights[FlockID],$A2,reg_WeeklyWeights[Date],$M2),0)) | O2: =IF($A2="","",IFERROR($K2/($I2*$N2/1000),0)) | P2: =IF($A2="","",IFERROR($N2/$F2,0)) | Q2: =IF($A2="","",SUMIFS(reg_Expenses[Amount_ZMW],reg_Expenses[FlockID],$A2)) | R2: =IF($A2="","",SUMIFS(reg_MedicineStock[TotalCost_ZMW],reg_MedicineStock[FlockID],$A2)) | S2: =IF($A2="","",SUMIFS(reg_Sales_Dispatch[TotalValue_ZMW],reg_Sales_Dispatch[FlockID],$A2)) | T2: =IF($A2="","",SUMIFS(reg_Sales_Dispatch[BirdsDispatched],reg_Sales_Dispatch[FlockID],$A2)) | U2: =IF($A2="","",IFERROR(($Q2+$L2+$R2)/$G2,0)) | V2: =IF($A2="","",IFERROR(($Q2+$L2+$R2)/($I2*$N2/1000),0)) | W2: =IF($A2="","",$S2-$Q2-$L2-$R2) | X2: =IF($A2="","",IFERROR(($Q2+$L2+$R2)/IF($T2>0,$T2,$G2),0))
A3: =IFERROR(INDEX(reg_Flocks[FlockID],ROW()-1),"") | B3: =IF($A3="","",IFERROR(INDEX(mst_Houses[HouseCode],MATCH(INDEX(reg_Flocks[HouseID],MATCH($A3,reg_Flocks[FlockID],0)),mst_Houses[HouseID],0)),"")) | C3: =IF($A3="","",IFERROR(INDEX(mst_Breeds[BreedName],MATCH(INDEX(reg_Flocks[BreedID],MATCH($A3,reg_Flocks[FlockID],0)),mst_Breeds[BreedID],0)),"")) | D3: =IF($A3="","",INDEX(reg_Flocks[PlacedDate],MATCH($A3,reg_Flocks[FlockID],0))) | E3: =IF($A3="","",INDEX(reg_Flocks[Status],MATCH($A3,reg_Flocks[FlockID],0))) | F3: =IF($A3="","",TODAY()-$D3) | G3: =IF($A3="","",INDEX(reg_Flocks[InitialBirdCount],MATCH($A3,reg_Flocks[FlockID],0))) | H3: =IF($A3="","",SUMIFS(reg_DailyMortality[MortalityCount],reg_DailyMortality[FlockID],$A3)) | I3: =IF($A3="","",$G3-$H3) | J3: =IF($A3="","",IFERROR($I3/$G3,0)) | K3: =IF($A3="","",SUMIFS(reg_FeedConsumption[KgUsed],reg_FeedConsumption[FlockID],$A3)) | L3: =IF($A3="","",SUMIFS(reg_FeedConsumption[CostZMW],reg_FeedConsumption[FlockID],$A3)) | M3: =IF($A3="","",IFERROR(_xlfn.MAXIFS(reg_WeeklyWeights[Date],reg_WeeklyWeights[FlockID],$A3),"")) | N3: =IF($A3="","",IFERROR(SUMIFS(reg_WeeklyWeights[AvgBodyWeightG],reg_WeeklyWeights[FlockID],$A3,reg_WeeklyWeights[Date],$M3),0)) | O3: =IF($A3="","",IFERROR($K3/($I3*$N3/1000),0)) | P3: =IF($A3="","",IFERROR($N3/$F3,0)) | Q3: =IF($A3="","",SUMIFS(reg_Expenses[Amount_ZMW],reg_Expenses[FlockID],$A3)) | R3: =IF($A3="","",SUMIFS(reg_MedicineStock[TotalCost_ZMW],reg_MedicineStock[FlockID],$A3)) | S3: =IF($A3="","",SUMIFS(reg_Sales_Dispatch[TotalValue_ZMW],reg_Sales_Dispatch[FlockID],$A3)) | T3: =IF($A3="","",SUMIFS(reg_Sales_Dispatch[BirdsDispatched],reg_Sales_Dispatch[FlockID],$A3)) | U3: =IF($A3="","",IFERROR(($Q3+$L3+$R3)/$G3,0)) | V3: =IF($A3="","",IFERROR(($Q3+$L3+$R3)/($I3*$N3/1000),0)) | W3: =IF($A3="","",$S3-$Q3-$L3-$R3) | X3: =IF($A3="","",IFERROR(($Q3+$L3+$R3)/IF($T3>0,$T3,$G3),0))
A4: =IFERROR(INDEX(reg_Flocks[FlockID],ROW()-1),"") | B4: =IF($A4="","",IFERROR(INDEX(mst_Houses[HouseCode],MATCH(INDEX(reg_Flocks[HouseID],MATCH($A4,reg_Flocks[FlockID],0)),mst_Houses[HouseID],0)),"")) | C4: =IF($A4="","",IFERROR(INDEX(mst_Breeds[BreedName],MATCH(INDEX(reg_Flocks[BreedID],MATCH($A4,reg_Flocks[FlockID],0)),mst_Breeds[BreedID],0)),"")) | D4: =IF($A4="","",INDEX(reg_Flocks[PlacedDate],MATCH($A4,reg_Flocks[FlockID],0))) | E4: =IF($A4="","",INDEX(reg_Flocks[Status],MATCH($A4,reg_Flocks[FlockID],0))) | F4: =IF($A4="","",TODAY()-$D4) | G4: =IF($A4="","",INDEX(reg_Flocks[InitialBirdCount],MATCH($A4,reg_Flocks[FlockID],0))) | H4: =IF($A4="","",SUMIFS(reg_DailyMortality[MortalityCount],reg_DailyMortality[FlockID],$A4)) | I4: =IF($A4="","",$G4-$H4) | J4: =IF($A4="","",IFERROR($I4/$G4,0)) | K4: =IF($A4="","",SUMIFS(reg_FeedConsumption[KgUsed],reg_FeedConsumption[FlockID],$A4)) | L4: =IF($A4="","",SUMIFS(reg_FeedConsumption[CostZMW],reg_FeedConsumption[FlockID],$A4)) | M4: =IF($A4="","",IFERROR(_xlfn.MAXIFS(reg_WeeklyWeights[Date],reg_WeeklyWeights[FlockID],$A4),"")) | N4: =IF($A4="","",IFERROR(SUMIFS(reg_WeeklyWeights[AvgBodyWeightG],reg_WeeklyWeights[FlockID],$A4,reg_WeeklyWeights[Date],$M4),0)) | O4: =IF($A4="","",IFERROR($K4/($I4*$N4/1000),0)) | P4: =IF($A4="","",IFERROR($N4/$F4,0)) | Q4: =IF($A4="","",SUMIFS(reg_Expenses[Amount_ZMW],reg_Expenses[FlockID],$A4)) | R4: =IF($A4="","",SUMIFS(reg_MedicineStock[TotalCost_ZMW],reg_MedicineStock[FlockID],$A4)) | S4: =IF($A4="","",SUMIFS(reg_Sales_Dispatch[TotalValue_ZMW],reg_Sales_Dispatch[FlockID],$A4)) | T4: =IF($A4="","",SUMIFS(reg_Sales_Dispatch[BirdsDispatched],reg_Sales_Dispatch[FlockID],$A4)) | U4: =IF($A4="","",IFERROR(($Q4+$L4+$R4)/$G4,0)) | V4: =IF($A4="","",IFERROR(($Q4+$L4+$R4)/($I4*$N4/1000),0)) | W4: =IF($A4="","",$S4-$Q4-$L4-$R4) | X4: =IF($A4="","",IFERROR(($Q4+$L4+$R4)/IF($T4>0,$T4,$G4),0))
A5: =IFERROR(INDEX(reg_Flocks[FlockID],ROW()-1),"") | B5: =IF($A5="","",IFERROR(INDEX(mst_Houses[HouseCode],MATCH(INDEX(reg_Flocks[HouseID],MATCH($A5,reg_Flocks[FlockID],0)),mst_Houses[HouseID],0)),"")) | C5: =IF($A5="","",IFERROR(INDEX(mst_Breeds[BreedName],MATCH(INDEX(reg_Flocks[BreedID],MATCH($A5,reg_Flocks[FlockID],0)),mst_Breeds[BreedID],0)),"")) | D5: =IF($A5="","",INDEX(reg_Flocks[PlacedDate],MATCH($A5,reg_Flocks[FlockID],0))) | E5: =IF($A5="","",INDEX(reg_Flocks[Status],MATCH($A5,reg_Flocks[FlockID],0))) | F5: =IF($A5="","",TODAY()-$D5) | G5: =IF($A5="","",INDEX(reg_Flocks[InitialBirdCount],MATCH($A5,reg_Flocks[FlockID],0))) | H5: =IF($A5="","",SUMIFS(reg_DailyMortality[MortalityCount],reg_DailyMortality[FlockID],$A5)) | I5: =IF($A5="","",$G5-$H5) | J5: =IF($A5="","",IFERROR($I5/$G5,0)) | K5: =IF($A5="","",SUMIFS(reg_FeedConsumption[KgUsed],reg_FeedConsumption[FlockID],$A5)) | L5: =IF($A5="","",SUMIFS(reg_FeedConsumption[CostZMW],reg_FeedConsumption[FlockID],$A5)) | M5: =IF($A5="","",IFERROR(_xlfn.MAXIFS(reg_WeeklyWeights[Date],reg_WeeklyWeights[FlockID],$A5),"")) | N5: =IF($A5="","",IFERROR(SUMIFS(reg_WeeklyWeights[AvgBodyWeightG],reg_WeeklyWeights[FlockID],$A5,reg_WeeklyWeights[Date],$M5),0)) | O5: =IF($A5="","",IFERROR($K5/($I5*$N5/1000),0)) | P5: =IF($A5="","",IFERROR($N5/$F5,0)) | Q5: =IF($A5="","",SUMIFS(reg_Expenses[Amount_ZMW],reg_Expenses[FlockID],$A5)) | R5: =IF($A5="","",SUMIFS(reg_MedicineStock[TotalCost_ZMW],reg_MedicineStock[FlockID],$A5)) | S5: =IF($A5="","",SUMIFS(reg_Sales_Dispatch[TotalValue_ZMW],reg_Sales_Dispatch[FlockID],$A5)) | T5: =IF($A5="","",SUMIFS(reg_Sales_Dispatch[BirdsDispatched],reg_Sales_Dispatch[FlockID],$A5)) | U5: =IF($A5="","",IFERROR(($Q5+$L5+$R5)/$G5,0)) | V5: =IF($A5="","",IFERROR(($Q5+$L5+$R5)/($I5*$N5/1000),0)) | W5: =IF($A5="","",$S5-$Q5-$L5-$R5) | X5: =IF($A5="","",IFERROR(($Q5+$L5+$R5)/IF($T5>0,$T5,$G5),0))
A6: =IFERROR(INDEX(reg_Flocks[FlockID],ROW()-1),"") | B6: =IF($A6="","",IFERROR(INDEX(mst_Houses[HouseCode],MATCH(INDEX(reg_Flocks[HouseID],MATCH($A6,reg_Flocks[FlockID],0)),mst_Houses[HouseID],0)),"")) | C6: =IF($A6="","",IFERROR(INDEX(mst_Breeds[BreedName],MATCH(INDEX(reg_Flocks[BreedID],MATCH($A6,reg_Flocks[FlockID],0)),mst_Breeds[BreedID],0)),"")) | D6: =IF($A6="","",INDEX(reg_Flocks[PlacedDate],MATCH($A6,reg_Flocks[FlockID],0))) | E6: =IF($A6="","",INDEX(reg_Flocks[Status],MATCH($A6,reg_Flocks[FlockID],0))) | F6: =IF($A6="","",TODAY()-$D6) | G6: =IF($A6="","",INDEX(reg_Flocks[InitialBirdCount],MATCH($A6,reg_Flocks[FlockID],0))) | H6: =IF($A6="","",SUMIFS(reg_DailyMortality[MortalityCount],reg_DailyMortality[FlockID],$A6)) | I6: =IF($A6="","",$G6-$H6) | J6: =IF($A6="","",IFERROR($I6/$G6,0)) | K6: =IF($A6="","",SUMIFS(reg_FeedConsumption[KgUsed],reg_FeedConsumption[FlockID],$A6)) | L6: =IF($A6="","",SUMIFS(reg_FeedConsumption[CostZMW],reg_FeedConsumption[FlockID],$A6)) | M6: =IF($A6="","",IFERROR(_xlfn.MAXIFS(reg_WeeklyWeights[Date],reg_WeeklyWeights[FlockID],$A6),"")) | N6: =IF($A6="","",IFERROR(SUMIFS(reg_WeeklyWeights[AvgBodyWeightG],reg_WeeklyWeights[FlockID],$A6,reg_WeeklyWeights[Date],$M6),0)) | O6: =IF($A6="","",IFERROR($K6/($I6*$N6/1000),0)) | P6: =IF($A6="","",IFERROR($N6/$F6,0)) | Q6: =IF($A6="","",SUMIFS(reg_Expenses[Amount_ZMW],reg_Expenses[FlockID],$A6)) | R6: =IF($A6="","",SUMIFS(reg_MedicineStock[TotalCost_ZMW],reg_MedicineStock[FlockID],$A6)) | S6: =IF($A6="","",SUMIFS(reg_Sales_Dispatch[TotalValue_ZMW],reg_Sales_Dispatch[FlockID],$A6)) | T6: =IF($A6="","",SUMIFS(reg_Sales_Dispatch[BirdsDispatched],reg_Sales_Dispatch[FlockID],$A6)) | U6: =IF($A6="","",IFERROR(($Q6+$L6+$R6)/$G6,0)) | V6: =IF($A6="","",IFERROR(($Q6+$L6+$R6)/($I6*$N6/1000),0)) | W6: =IF($A6="","",$S6-$Q6-$L6-$R6) | X6: =IF($A6="","",IFERROR(($Q6+$L6+$R6)/IF($T6>0,$T6,$G6),0))
A7: =IFERROR(INDEX(reg_Flocks[FlockID],ROW()-1),"") | B7: =IF($A7="","",IFERROR(INDEX(mst_Houses[HouseCode],MATCH(INDEX(reg_Flocks[HouseID],MATCH($A7,reg_Flocks[FlockID],0)),mst_Houses[HouseID],0)),"")) | C7: =IF($A7="","",IFERROR(INDEX(mst_Breeds[BreedName],MATCH(INDEX(reg_Flocks[BreedID],MATCH($A7,reg_Flocks[FlockID],0)),mst_Breeds[BreedID],0)),"")) | D7: =IF($A7="","",INDEX(reg_Flocks[PlacedDate],MATCH($A7,reg_Flocks[FlockID],0))) | E7: =IF($A7="","",INDEX(reg_Flocks[Status],MATCH($A7,reg_Flocks[FlockID],0))) | F7: =IF($A7="","",TODAY()-$D7) | G7: =IF($A7="","",INDEX(reg_Flocks[InitialBirdCount],MATCH($A7,reg_Flocks[FlockID],0))) | H7: =IF($A7="","",SUMIFS(reg_DailyMortality[MortalityCount],reg_DailyMortality[FlockID],$A7)) | I7: =IF($A7="","",$G7-$H7) | J7: =IF($A7="","",IFERROR($I7/$G7,0)) | K7: =IF($A7="","",SUMIFS(reg_FeedConsumption[KgUsed],reg_FeedConsumption[FlockID],$A7)) | L7: =IF($A7="","",SUMIFS(reg_FeedConsumption[CostZMW],reg_FeedConsumption[FlockID],$A7)) | M7: =IF($A7="","",IFERROR(_xlfn.MAXIFS(reg_WeeklyWeights[Date],reg_WeeklyWeights[FlockID],$A7),"")) | N7: =IF($A7="","",IFERROR(SUMIFS(reg_WeeklyWeights[AvgBodyWeightG],reg_WeeklyWeights[FlockID],$A7,reg_WeeklyWeights[Date],$M7),0)) | O7: =IF($A7="","",IFERROR($K7/($I7*$N7/1000),0)) | P7: =IF($A7="","",IFERROR($N7/$F7,0)) | Q7: =IF($A7="","",SUMIFS(reg_Expenses[Amount_ZMW],reg_Expenses[FlockID],$A7)) | R7: =IF($A7="","",SUMIFS(reg_MedicineStock[TotalCost_ZMW],reg_MedicineStock[FlockID],$A7)) | S7: =IF($A7="","",SUMIFS(reg_Sales_Dispatch[TotalValue_ZMW],reg_Sales_Dispatch[FlockID],$A7)) | T7: =IF($A7="","",SUMIFS(reg_Sales_Dispatch[BirdsDispatched],reg_Sales_Dispatch[FlockID],$A7)) | U7: =IF($A7="","",IFERROR(($Q7+$L7+$R7)/$G7,0)) | V7: =IF($A7="","",IFERROR(($Q7+$L7+$R7)/($I7*$N7/1000),0)) | W7: =IF($A7="","",$S7-$Q7-$L7-$R7) | X7: =IF($A7="","",IFERROR(($Q7+$L7+$R7)/IF($T7>0,$T7,$G7),0))
A8: =IFERROR(INDEX(reg_Flocks[FlockID],ROW()-1),"") | B8: =IF($A8="","",IFERROR(INDEX(mst_Houses[HouseCode],MATCH(INDEX(reg_Flocks[HouseID],MATCH($A8,reg_Flocks[FlockID],0)),mst_Houses[HouseID],0)),"")) | C8: =IF($A8="","",IFERROR(INDEX(mst_Breeds[BreedName],MATCH(INDEX(reg_Flocks[BreedID],MATCH($A8,reg_Flocks[FlockID],0)),mst_Breeds[BreedID],0)),"")) | D8: =IF($A8="","",INDEX(reg_Flocks[PlacedDate],MATCH($A8,reg_Flocks[FlockID],0))) | E8: =IF($A8="","",INDEX(reg_Flocks[Status],MATCH($A8,reg_Flocks[FlockID],0))) | F8: =IF($A8="","",TODAY()-$D8) | G8: =IF($A8="","",INDEX(reg_Flocks[InitialBirdCount],MATCH($A8,reg_Flocks[FlockID],0))) | H8: =IF($A8="","",SUMIFS(reg_DailyMortality[MortalityCount],reg_DailyMortality[FlockID],$A8)) | I8: =IF($A8="","",$G8-$H8) | J8: =IF($A8="","",IFERROR($I8/$G8,0)) | K8: =IF($A8="","",SUMIFS(reg_FeedConsumption[KgUsed],reg_FeedConsumption[FlockID],$A8)) | L8: =IF($A8="","",SUMIFS(reg_FeedConsumption[CostZMW],reg_FeedConsumption[FlockID],$A8)) | M8: =IF($A8="","",IFERROR(_xlfn.MAXIFS(reg_WeeklyWeights[Date],reg_WeeklyWeights[FlockID],$A8),"")) | N8: =IF($A8="","",IFERROR(SUMIFS(reg_WeeklyWeights[AvgBodyWeightG],reg_WeeklyWeights[FlockID],$A8,reg_WeeklyWeights[Date],$M8),0)) | O8: =IF($A8="","",IFERROR($K8/($I8*$N8/1000),0)) | P8: =IF($A8="","",IFERROR($N8/$F8,0)) | Q8: =IF($A8="","",SUMIFS(reg_Expenses[Amount_ZMW],reg_Expenses[FlockID],$A8)) | R8: =IF($A8="","",SUMIFS(reg_MedicineStock[TotalCost_ZMW],reg_MedicineStock[FlockID],$A8)) | S8: =IF($A8="","",SUMIFS(reg_Sales_Dispatch[TotalValue_ZMW],reg_Sales_Dispatch[FlockID],$A8)) | T8: =IF($A8="","",SUMIFS(reg_Sales_Dispatch[BirdsDispatched],reg_Sales_Dispatch[FlockID],$A8)) | U8: =IF($A8="","",IFERROR(($Q8+$L8+$R8)/$G8,0)) | V8: =IF($A8="","",IFERROR(($Q8+$L8+$R8)/($I8*$N8/1000),0)) | W8: =IF($A8="","",$S8-$Q8-$L8-$R8) | X8: =IF($A8="","",IFERROR(($Q8+$L8+$R8)/IF($T8>0,$T8,$G8),0))
A9: =IFERROR(INDEX(reg_Flocks[FlockID],ROW()-1),"") | B9: =IF($A9="","",IFERROR(INDEX(mst_Houses[HouseCode],MATCH(INDEX(reg_Flocks[HouseID],MATCH($A9,reg_Flocks[FlockID],0)),mst_Houses[HouseID],0)),"")) | C9: =IF($A9="","",IFERROR(INDEX(mst_Breeds[BreedName],MATCH(INDEX(reg_Flocks[BreedID],MATCH($A9,reg_Flocks[FlockID],0)),mst_Breeds[BreedID],0)),"")) | D9: =IF($A9="","",INDEX(reg_Flocks[PlacedDate],MATCH($A9,reg_Flocks[FlockID],0))) | E9: =IF($A9="","",INDEX(reg_Flocks[Status],MATCH($A9,reg_Flocks[FlockID],0))) | F9: =IF($A9="","",TODAY()-$D9) | G9: =IF($A9="","",INDEX(reg_Flocks[InitialBirdCount],MATCH($A9,reg_Flocks[FlockID],0))) | H9: =IF($A9="","",SUMIFS(reg_DailyMortality[MortalityCount],reg_DailyMortality[FlockID],$A9)) | I9: =IF($A9="","",$G9-$H9) | J9: =IF($A9="","",IFERROR($I9/$G9,0)) | K9: =IF($A9="","",SUMIFS(reg_FeedConsumption[KgUsed],reg_FeedConsumption[FlockID],$A9)) | L9: =IF($A9="","",SUMIFS(reg_FeedConsumption[CostZMW],reg_FeedConsumption[FlockID],$A9)) | M9: =IF($A9="","",IFERROR(_xlfn.MAXIFS(reg_WeeklyWeights[Date],reg_WeeklyWeights[FlockID],$A9),"")) | N9: =IF($A9="","",IFERROR(SUMIFS(reg_WeeklyWeights[AvgBodyWeightG],reg_WeeklyWeights[FlockID],$A9,reg_WeeklyWeights[Date],$M9),0)) | O9: =IF($A9="","",IFERROR($K9/($I9*$N9/1000),0)) | P9: =IF($A9="","",IFERROR($N9/$F9,0)) | Q9: =IF($A9="","",SUMIFS(reg_Expenses[Amount_ZMW],reg_Expenses[FlockID],$A9)) | R9: =IF($A9="","",SUMIFS(reg_MedicineStock[TotalCost_ZMW],reg_MedicineStock[FlockID],$A9)) | S9: =IF($A9="","",SUMIFS(reg_Sales_Dispatch[TotalValue_ZMW],reg_Sales_Dispatch[FlockID],$A9)) | T9: =IF($A9="","",SUMIFS(reg_Sales_Dispatch[BirdsDispatched],reg_Sales_Dispatch[FlockID],$A9)) | U9: =IF($A9="","",IFERROR(($Q9+$L9+$R9)/$G9,0)) | V9: =IF($A9="","",IFERROR(($Q9+$L9+$R9)/($I9*$N9/1000),0)) | W9: =IF($A9="","",$S9-$Q9-$L9-$R9) | X9: =IF($A9="","",IFERROR(($Q9+$L9+$R9)/IF($T9>0,$T9,$G9),0))
A10: =IFERROR(INDEX(reg_Flocks[FlockID],ROW()-1),"") | B10: =IF($A10="","",IFERROR(INDEX(mst_Houses[HouseCode],MATCH(INDEX(reg_Flocks[HouseID],MATCH($A10,reg_Flocks[FlockID],0)),mst_Houses[HouseID],0)),"")) | C10: =IF($A10="","",IFERROR(INDEX(mst_Breeds[BreedName],MATCH(INDEX(reg_Flocks[BreedID],MATCH($A10,reg_Flocks[FlockID],0)),mst_Breeds[BreedID],0)),"")) | D10: =IF($A10="","",INDEX(reg_Flocks[PlacedDate],MATCH($A10,reg_Flocks[FlockID],0))) | E10: =IF($A10="","",INDEX(reg_Flocks[Status],MATCH($A10,reg_Flocks[FlockID],0))) | F10: =IF($A10="","",TODAY()-$D10) | G10: =IF($A10="","",INDEX(reg_Flocks[InitialBirdCount],MATCH($A10,reg_Flocks[FlockID],0))) | H10: =IF($A10="","",SUMIFS(reg_DailyMortality[MortalityCount],reg_DailyMortality[FlockID],$A10)) | I10: =IF($A10="","",$G10-$H10) | J10: =IF($A10="","",IFERROR($I10/$G10,0)) | K10: =IF($A10="","",SUMIFS(reg_FeedConsumption[KgUsed],reg_FeedConsumption[FlockID],$A10)) | L10: =IF($A10="","",SUMIFS(reg_FeedConsumption[CostZMW],reg_FeedConsumption[FlockID],$A10)) | M10: =IF($A10="","",IFERROR(_xlfn.MAXIFS(reg_WeeklyWeights[Date],reg_WeeklyWeights[FlockID],$A10),"")) | N10: =IF($A10="","",IFERROR(SUMIFS(reg_WeeklyWeights[AvgBodyWeightG],reg_WeeklyWeights[FlockID],$A10,reg_WeeklyWeights[Date],$M10),0)) | O10: =IF($A10="","",IFERROR($K10/($I10*$N10/1000),0)) | P10: =IF($A10="","",IFERROR($N10/$F10,0)) | Q10: =IF($A10="","",SUMIFS(reg_Expenses[Amount_ZMW],reg_Expenses[FlockID],$A10)) | R10: =IF($A10="","",SUMIFS(reg_MedicineStock[TotalCost_ZMW],reg_MedicineStock[FlockID],$A10)) | S10: =IF($A10="","",SUMIFS(reg_Sales_Dispatch[TotalValue_ZMW],reg_Sales_Dispatch[FlockID],$A10)) | T10: =IF($A10="","",SUMIFS(reg_Sales_Dispatch[BirdsDispatched],reg_Sales_Dispatch[FlockID],$A10)) | U10: =IF($A10="","",IFERROR(($Q10+$L10+$R10)/$G10,0)) | V10: =IF($A10="","",IFERROR(($Q10+$L10+$R10)/($I10*$N10/1000),0)) | W10: =IF($A10="","",$S10-$Q10-$L10-$R10) | X10: =IF($A10="","",IFERROR(($Q10+$L10+$R10)/IF($T10>0,$T10,$G10),0))
A11: =IFERROR(INDEX(reg_Flocks[FlockID],ROW()-1),"") | B11: =IF($A11="","",IFERROR(INDEX(mst_Houses[HouseCode],MATCH(INDEX(reg_Flocks[HouseID],MATCH($A11,reg_Flocks[FlockID],0)),mst_Houses[HouseID],0)),"")) | C11: =IF($A11="","",IFERROR(INDEX(mst_Breeds[BreedName],MATCH(INDEX(reg_Flocks[BreedID],MATCH($A11,reg_Flocks[FlockID],0)),mst_Breeds[BreedID],0)),"")) | D11: =IF($A11="","",INDEX(reg_Flocks[PlacedDate],MATCH($A11,reg_Flocks[FlockID],0))) | E11: =IF($A11="","",INDEX(reg_Flocks[Status],MATCH($A11,reg_Flocks[FlockID],0))) | F11: =IF($A11="","",TODAY()-$D11) | G11: =IF($A11="","",INDEX(reg_Flocks[InitialBirdCount],MATCH($A11,reg_Flocks[FlockID],0))) | H11: =IF($A11="","",SUMIFS(reg_DailyMortality[MortalityCount],reg_DailyMortality[FlockID],$A11)) | I11: =IF($A11="","",$G11-$H11) | J11: =IF($A11="","",IFERROR($I11/$G11,0)) | K11: =IF($A11="","",SUMIFS(reg_FeedConsumption[KgUsed],reg_FeedConsumption[FlockID],$A11)) | L11: =IF($A11="","",SUMIFS(reg_FeedConsumption[CostZMW],reg_FeedConsumption[FlockID],$A11)) | M11: =IF($A11="","",IFERROR(_xlfn.MAXIFS(reg_WeeklyWeights[Date],reg_WeeklyWeights[FlockID],$A11),"")) | N11: =IF($A11="","",IFERROR(SUMIFS(reg_WeeklyWeights[AvgBodyWeightG],reg_WeeklyWeights[FlockID],$A11,reg_WeeklyWeights[Date],$M11),0)) | O11: =IF($A11="","",IFERROR($K11/($I11*$N11/1000),0)) | P11: =IF($A11="","",IFERROR($N11/$F11,0)) | Q11: =IF($A11="","",SUMIFS(reg_Expenses[Amount_ZMW],reg_Expenses[FlockID],$A11)) | R11: =IF($A11="","",SUMIFS(reg_MedicineStock[TotalCost_ZMW],reg_MedicineStock[FlockID],$A11)) | S11: =IF($A11="","",SUMIFS(reg_Sales_Dispatch[TotalValue_ZMW],reg_Sales_Dispatch[FlockID],$A11)) | T11: =IF($A11="","",SUMIFS(reg_Sales_Dispatch[BirdsDispatched],reg_Sales_Dispatch[FlockID],$A11)) | U11: =IF($A11="","",IFERROR(($Q11+$L11+$R11)/$G11,0)) | V11: =IF($A11="","",IFERROR(($Q11+$L11+$R11)/($I11*$N11/1000),0)) | W11: =IF($A11="","",$S11-$Q11-$L11-$R11) | X11: =IF($A11="","",IFERROR(($Q11+$L11+$R11)/IF($T11>0,$T11,$G11),0))
A12: =IFERROR(INDEX(reg_Flocks[FlockID],ROW()-1),"") | B12: =IF($A12="","",IFERROR(INDEX(mst_Houses[HouseCode],MATCH(INDEX(reg_Flocks[HouseID],MATCH($A12,reg_Flocks[FlockID],0)),mst_Houses[HouseID],0)),"")) | C12: =IF($A12="","",IFERROR(INDEX(mst_Breeds[BreedName],MATCH(INDEX(reg_Flocks[BreedID],MATCH($A12,reg_Flocks[FlockID],0)),mst_Breeds[BreedID],0)),"")) | D12: =IF($A12="","",INDEX(reg_Flocks[PlacedDate],MATCH($A12,reg_Flocks[FlockID],0))) | E12: =IF($A12="","",INDEX(reg_Flocks[Status],MATCH($A12,reg_Flocks[FlockID],0))) | F12: =IF($A12="","",TODAY()-$D12) | G12: =IF($A12="","",INDEX(reg_Flocks[InitialBirdCount],MATCH($A12,reg_Flocks[FlockID],0))) | H12: =IF($A12="","",SUMIFS(reg_DailyMortality[MortalityCount],reg_DailyMortality[FlockID],$A12)) | I12: =IF($A12="","",$G12-$H12) | J12: =IF($A12="","",IFERROR($I12/$G12,0)) | K12: =IF($A12="","",SUMIFS(reg_FeedConsumption[KgUsed],reg_FeedConsumption[FlockID],$A12)) | L12: =IF($A12="","",SUMIFS(reg_FeedConsumption[CostZMW],reg_FeedConsumption[FlockID],$A12)) | M12: =IF($A12="","",IFERROR(_xlfn.MAXIFS(reg_WeeklyWeights[Date],reg_WeeklyWeights[FlockID],$A12),"")) | N12: =IF($A12="","",IFERROR(SUMIFS(reg_WeeklyWeights[AvgBodyWeightG],reg_WeeklyWeights[FlockID],$A12,reg_WeeklyWeights[Date],$M12),0)) | O12: =IF($A12="","",IFERROR($K12/($I12*$N12/1000),0)) | P12: =IF($A12="","",IFERROR($N12/$F12,0)) | Q12: =IF($A12="","",SUMIFS(reg_Expenses[Amount_ZMW],reg_Expenses[FlockID],$A12)) | R12: =IF($A12="","",SUMIFS(reg_MedicineStock[TotalCost_ZMW],reg_MedicineStock[FlockID],$A12)) | S12: =IF($A12="","",SUMIFS(reg_Sales_Dispatch[TotalValue_ZMW],reg_Sales_Dispatch[FlockID],$A12)) | T12: =IF($A12="","",SUMIFS(reg_Sales_Dispatch[BirdsDispatched],reg_Sales_Dispatch[FlockID],$A12)) | U12: =IF($A12="","",IFERROR(($Q12+$L12+$R12)/$G12,0)) | V12: =IF($A12="","",IFERROR(($Q12+$L12+$R12)/($I12*$N12/1000),0)) | W12: =IF($A12="","",$S12-$Q12-$L12-$R12) | X12: =IF($A12="","",IFERROR(($Q12+$L12+$R12)/IF($T12>0,$T12,$G12),0))
A13: =IFERROR(INDEX(reg_Flocks[FlockID],ROW()-1),"") | B13: =IF($A13="","",IFERROR(INDEX(mst_Houses[HouseCode],MATCH(INDEX(reg_Flocks[HouseID],MATCH($A13,reg_Flocks[FlockID],0)),mst_Houses[HouseID],0)),"")) | C13: =IF($A13="","",IFERROR(INDEX(mst_Breeds[BreedName],MATCH(INDEX(reg_Flocks[BreedID],MATCH($A13,reg_Flocks[FlockID],0)),mst_Breeds[BreedID],0)),"")) | D13: =IF($A13="","",INDEX(reg_Flocks[PlacedDate],MATCH($A13,reg_Flocks[FlockID],0))) | E13: =IF($A13="","",INDEX(reg_Flocks[Status],MATCH($A13,reg_Flocks[FlockID],0))) | F13: =IF($A13="","",TODAY()-$D13) | G13: =IF($A13="","",INDEX(reg_Flocks[InitialBirdCount],MATCH($A13,reg_Flocks[FlockID],0))) | H13: =IF($A13="","",SUMIFS(reg_DailyMortality[MortalityCount],reg_DailyMortality[FlockID],$A13)) | I13: =IF($A13="","",$G13-$H13) | J13: =IF($A13="","",IFERROR($I13/$G13,0)) | K13: =IF($A13="","",SUMIFS(reg_FeedConsumption[KgUsed],reg_FeedConsumption[FlockID],$A13)) | L13: =IF($A13="","",SUMIFS(reg_FeedConsumption[CostZMW],reg_FeedConsumption[FlockID],$A13)) | M13: =IF($A13="","",IFERROR(_xlfn.MAXIFS(reg_WeeklyWeights[Date],reg_WeeklyWeights[FlockID],$A13),"")) | N13: =IF($A13="","",IFERROR(SUMIFS(reg_WeeklyWeights[AvgBodyWeightG],reg_WeeklyWeights[FlockID],$A13,reg_WeeklyWeights[Date],$M13),0)) | O13: =IF($A13="","",IFERROR($K13/($I13*$N13/1000),0)) | P13: =IF($A13="","",IFERROR($N13/$F13,0)) | Q13: =IF($A13="","",SUMIFS(reg_Expenses[Amount_ZMW],reg_Expenses[FlockID],$A13)) | R13: =IF($A13="","",SUMIFS(reg_MedicineStock[TotalCost_ZMW],reg_MedicineStock[FlockID],$A13)) | S13: =IF($A13="","",SUMIFS(reg_Sales_Dispatch[TotalValue_ZMW],reg_Sales_Dispatch[FlockID],$A13)) | T13: =IF($A13="","",SUMIFS(reg_Sales_Dispatch[BirdsDispatched],reg_Sales_Dispatch[FlockID],$A13)) | U13: =IF($A13="","",IFERROR(($Q13+$L13+$R13)/$G13,0)) | V13: =IF($A13="","",IFERROR(($Q13+$L13+$R13)/($I13*$N13/1000),0)) | W13: =IF($A13="","",$S13-$Q13-$L13-$R13) | X13: =IF($A13="","",IFERROR(($Q13+$L13+$R13)/IF($T13>0,$T13,$G13),0))
... A31: =IFERROR(INDEX(reg_Flocks[FlockID],ROW()-1),"") | B31: =IF($A31="","",IFERROR(INDEX(mst_Houses[HouseCode],MATCH(INDEX(reg_Flocks[HouseID],MATCH($A31,reg_Flocks[FlockID],0)),mst_Houses[HouseID],0)),"")) | C31: =IF($A31="","",IFERROR(INDEX(mst_Breeds[BreedName],MATCH(INDEX(reg_Flocks[BreedID],MATCH($A31,reg_Flocks[FlockID],0)),mst_Breeds[BreedID],0)),"")) | D31: =IF($A31="","",INDEX(reg_Flocks[PlacedDate],MATCH($A31,reg_Flocks[FlockID],0))) | E31: =IF($A31="","",INDEX(reg_Flocks[Status],MATCH($A31,reg_Flocks[FlockID],0))) | F31: =IF($A31="","",TODAY()-$D31) | G31: =IF($A31="","",INDEX(reg_Flocks[InitialBirdCount],MATCH($A31,reg_Flocks[FlockID],0))) | H31: =IF($A31="","",SUMIFS(reg_DailyMortality[MortalityCount],reg_DailyMortality[FlockID],$A31)) | I31: =IF($A31="","",$G31-$H31) | J31: =IF($A31="","",IFERROR($I31/$G31,0)) | K31: =IF($A31="","",SUMIFS(reg_FeedConsumption[KgUsed],reg_FeedConsumption[FlockID],$A31)) | L31: =IF($A31="","",SUMIFS(reg_FeedConsumption[CostZMW],reg_FeedConsumption[FlockID],$A31)) | M31: =IF($A31="","",IFERROR(_xlfn.MAXIFS(reg_WeeklyWeights[Date],reg_WeeklyWeights[FlockID],$A31),"")) | N31: =IF($A31="","",IFERROR(SUMIFS(reg_WeeklyWeights[AvgBodyWeightG],reg_WeeklyWeights[FlockID],$A31,reg_WeeklyWeights[Date],$M31),0)) | O31: =IF($A31="","",IFERROR($K31/($I31*$N31/1000),0)) | P31: =IF($A31="","",IFERROR($N31/$F31,0)) | Q31: =IF($A31="","",SUMIFS(reg_Expenses[Amount_ZMW],reg_Expenses[FlockID],$A31)) | R31: =IF($A31="","",SUMIFS(reg_MedicineStock[TotalCost_ZMW],reg_MedicineStock[FlockID],$A31)) | S31: =IF($A31="","",SUMIFS(reg_Sales_Dispatch[TotalValue_ZMW],reg_Sales_Dispatch[FlockID],$A31)) | T31: =IF($A31="","",SUMIFS(reg_Sales_Dispatch[BirdsDispatched],reg_Sales_Dispatch[FlockID],$A31)) | U31: =IF($A31="","",IFERROR(($Q31+$L31+$R31)/$G31,0)) | V31: =IF($A31="","",IFERROR(($Q31+$L31+$R31)/($I31*$N31/1000),0)) | W31: =IF($A31="","",$S31-$Q31-$L31-$R31) | X31: =IF($A31="","",IFERROR(($Q31+$L31+$R31)/IF($T31>0,$T31,$G31),0))

Sheet Log_Audit
A1: LogID | B1: TableName | C1: Action | D1: RecordID | E1: FieldChanged | F1: OldValue | G1: NewValue | H1: UserName | I1: Timestamp

Sheet rpt_FlockPerformance
A1: FarmNow Limited
A3: Flock Performance Report
A4: ="Generated: "&TEXT(TODAY(),"dd mmm yyyy")&" | Prepared by: Farmnow Broiler Management System"
A6: Select Flock: | B6: FLK-001
A8: Metric | B8: Value
A9: House | B9: =INDEX(calc_KPI_Engine[HouseCode],MATCH($B$6,calc_KPI_Engine[FlockID],0))
A10: Breed | B10: =INDEX(calc_KPI_Engine[BreedName],MATCH($B$6,calc_KPI_Engine[FlockID],0))
A11: Placed Date | B11: =INDEX(calc_KPI_Engine[PlacedDate],MATCH($B$6,calc_KPI_Engine[FlockID],0))
A12: Status | B12: =INDEX(calc_KPI_Engine[Status],MATCH($B$6,calc_KPI_Engine[FlockID],0))
A13: Days On Farm | B13: =INDEX(calc_KPI_Engine[DaysOnFarm],MATCH($B$6,calc_KPI_Engine[FlockID],0))
A14: Initial Bird Count | B14: =INDEX(calc_KPI_Engine[InitialBirds],MATCH($B$6,calc_KPI_Engine[FlockID],0))
A15: Total Mortality | B15: =INDEX(calc_KPI_Engine[TotalMortality],MATCH($B$6,calc_KPI_Engine[FlockID],0))
A16: Current Bird Count | B16: =INDEX(calc_KPI_Engine[CurrentBirds],MATCH($B$6,calc_KPI_Engine[FlockID],0))
A17: Livability % | B17: =INDEX(calc_KPI_Engine[LivabilityPct],MATCH($B$6,calc_KPI_Engine[FlockID],0))
A18: Total Feed Used (Kg) | B18: =INDEX(calc_KPI_Engine[TotalFeedKg],MATCH($B$6,calc_KPI_Engine[FlockID],0))
A19: Latest Avg Body Weight (g) | B19: =INDEX(calc_KPI_Engine[LatestAvgWeightG],MATCH($B$6,calc_KPI_Engine[FlockID],0))
A20: FCR (Feed Conversion Ratio) | B20: =INDEX(calc_KPI_Engine[FCR],MATCH($B$6,calc_KPI_Engine[FlockID],0))
A21: ADG (g/day) | B21: =INDEX(calc_KPI_Engine[ADG_g],MATCH($B$6,calc_KPI_Engine[FlockID],0))
A22: Total Feed Cost (ZMW) | B22: =INDEX(calc_KPI_Engine[TotalFeedCost_ZMW],MATCH($B$6,calc_KPI_Engine[FlockID],0))
A23: Medicine Cost (ZMW) | B23: =INDEX(calc_KPI_Engine[MedicineCost_ZMW],MATCH($B$6,calc_KPI_Engine[FlockID],0))
A24: Total Other Expenses (ZMW) | B24: =INDEX(calc_KPI_Engine[TotalExpenses_ZMW],MATCH($B$6,calc_KPI_Engine[FlockID],0))
A25: Cost / Bird (ZMW) | B25: =INDEX(calc_KPI_Engine[CostPerBird_ZMW],MATCH($B$6,calc_KPI_Engine[FlockID],0))
A26: Cost / Kg Live Weight (ZMW) | B26: =INDEX(calc_KPI_Engine[CostPerKg_ZMW],MATCH($B$6,calc_KPI_Engine[FlockID],0))
A27: Break-even Price / Bird (ZMW) | B27: =INDEX(calc_KPI_Engine[BreakEvenPricePerBird_ZMW],MATCH($B$6,calc_KPI_Engine[FlockID],0))
A28: Total Sales Value (ZMW) | B28: =INDEX(calc_KPI_Engine[TotalSalesValue_ZMW],MATCH($B$6,calc_KPI_Engine[FlockID],0))
A29: Estimated Profit (ZMW) | B29: =INDEX(calc_KPI_Engine[EstimatedProfit_ZMW],MATCH($B$6,calc_KPI_Engine[FlockID],0))
A30: vs Breed Standard FCR | B30: =INDEX(mst_Breeds[StandardFCR],MATCH(INDEX(reg_Flocks[BreedID],MATCH($B$6,reg_Flocks[FlockID],0)),mst_Breeds[BreedID],0))

Sheet rpt_FinancialSummary
A1: FarmNow Limited
A3: Financial Summary Report - All Flocks
A4: ="Generated: "&TEXT(TODAY(),"dd mmm yyyy")&" | Prepared by: Farmnow Broiler Management System"
A6: Flock | B6: Status | C6: Feed Cost (ZMW) | D6: Medicine Cost (ZMW) | E6: Other Expenses (ZMW) | F6: Total Cost (ZMW) | G6: Sales Value (ZMW) | H6: Estimated Profit (ZMW) | I6: Cost / Bird (ZMW) | J6: Break-even Price/Bird (ZMW)
A7: =calc_KPI_Engine!A2 | B7: =calc_KPI_Engine!E2 | C7: =calc_KPI_Engine!L2 | D7: =calc_KPI_Engine!R2 | E7: =calc_KPI_Engine!Q2 | F7: =calc_KPI_Engine!L2+calc_KPI_Engine!Q2+calc_KPI_Engine!R2 | G7: =calc_KPI_Engine!S2 | H7: =calc_KPI_Engine!W2 | I7: =calc_KPI_Engine!U2 | J7: =calc_KPI_Engine!X2
